"""
T019: Integration test for error handling and fallback mechanisms
This test MUST FAIL until the workflow is implemented
"""

import pytest
import time
from unittest.mock import Mock, patch


class TestErrorHandlingWorkflowIntegration:
    """Integration tests for comprehensive error handling and recovery"""

    def test_ai_model_failure_fallback(self, sample_pdf_content):
        """Test fallback when primary AI model fails"""
        # This will FAIL until all components are implemented
        from ai_schema_generation.services import AIAnalyzer

        analyzer = AIAnalyzer()

        # Mock document for testing model failure
        test_document = {
            "id": "failure-test-001",
            "content": sample_pdf_content,
            "filename": "test_document.pdf",
            "file_type": "pdf"
        }

        # Primary model failure scenario
        with patch('ai_schema_generation.services.AIAnalyzer._call_primary_model') as mock_primary:
            mock_primary.side_effect = Exception("Primary model API timeout")

            # This will FAIL - AIAnalyzer doesn't exist
            try:
                analysis_result = analyzer.analyze_document_with_fallback({
                    "sample_document": test_document,
                    "analysis_options": {
                        "model_preference": "llama-scout",
                        "enable_fallback": True,
                        "fallback_model": "mistral-small"
                    }
                })

                # Should succeed with fallback model
                assert "analysis_result" in analysis_result
                analysis = analysis_result["analysis_result"]

                # Should indicate fallback was used
                assert analysis["model_used"] == "mistral-small"
                assert "fallback_used" in analysis_result["processing_metadata"]

            except Exception as exc_info:
                # If fallback also fails, should provide comprehensive error
                error_message = str(exc_info).lower()
                assert "fallback" in error_message or "retry" in error_message

    def test_network_interruption_recovery(self, sample_pdf_content):
        """Test recovery from network interruptions during analysis"""
        # This will FAIL until all components are implemented
        from ai_schema_generation.services import AIAnalyzer
        from ai_schema_generation.ui import UploadInterface

        analyzer = AIAnalyzer()
        uploader = UploadInterface()

        test_document = {
            "id": "network-test-001",
            "content": sample_pdf_content,
            "filename": "network_test.pdf",
            "file_type": "pdf"
        }

        # Simulate network interruption during analysis
        with patch('ai_schema_generation.services.AIAnalyzer._make_api_call') as mock_api:
            # First call fails with network error
            mock_api.side_effect = [
                ConnectionError("Network timeout"),
                {"analysis_result": {"id": "analysis-001", "status": "completed"}}  # Second call succeeds
            ]

            # This will FAIL - components don't exist
            upload_response = uploader.upload_sample_document({
                "document": test_document["content"],
                "filename": test_document["filename"]
            })

            document_id = upload_response["document_id"]

            # Monitor progress - should show retry attempts
            max_retries = 3
            retry_count = 0

            while retry_count < max_retries:
                progress_response = uploader.get_analysis_progress(document_id)

                if progress_response["status"] == "completed":
                    break
                elif progress_response["status"] == "failed":
                    # Should attempt retry
                    retry_response = analyzer.retry_analysis({
                        "sample_document_id": document_id,
                        "retry_options": {
                            "retry_reason": "network_error",
                            "max_retries": max_retries
                        }
                    })

                    if "analysis_result" in retry_response:
                        break

                retry_count += 1
                time.sleep(1)

            # Should eventually succeed or provide clear failure reason
            assert retry_count < max_retries, "Should recover from network interruption"

    def test_corrupted_document_handling(self):
        """Test handling of corrupted or invalid documents"""
        # This will FAIL until all components are implemented
        from ai_schema_generation.services import DocumentProcessor
        from ai_schema_generation.ui import UploadInterface

        processor = DocumentProcessor()
        uploader = UploadInterface()

        # Various corruption scenarios
        corruption_scenarios = [
            {
                "content": b"not a valid pdf",
                "filename": "fake.pdf",
                "error_type": "invalid_format"
            },
            {
                "content": b"\x00" * 100,  # Null bytes
                "filename": "corrupted.pdf",
                "error_type": "corruption"
            },
            {
                "content": b"",  # Empty file
                "filename": "empty.pdf",
                "error_type": "empty_file"
            }
        ]

        for scenario in corruption_scenarios:
            try:
                # This will FAIL - components don't exist
                upload_response = uploader.upload_sample_document({
                    "document": scenario["content"],
                    "filename": scenario["filename"]
                })

                # If upload succeeds, corruption should be detected during processing
                document_id = upload_response["document_id"]
                progress_response = uploader.get_analysis_progress(document_id)

                # Should fail gracefully with meaningful error
                assert progress_response["status"] in ["failed", "error"]
                if "error_message" in progress_response:
                    error_msg = progress_response["error_message"].lower()
                    assert any(term in error_msg for term in ["corrupt", "invalid", "format", "empty"])

            except ValueError as exc_info:
                # Should catch corruption during upload validation
                error_message = str(exc_info).lower()
                expected_terms = ["corrupt", "invalid", "format", "empty", "size"]
                assert any(term in error_message for term in expected_terms)

    def test_storage_system_failure_recovery(self, sample_pdf_content):
        """Test recovery from storage system failures"""
        # This will FAIL until all components are implemented
        from ai_schema_generation.services import SchemaGenerator
        from ai_schema_generation.storage import SampleDocumentStorage

        generator = SchemaGenerator()
        storage = SampleDocumentStorage()

        # Mock generated schema
        generated_schema = {
            "id": "schema-storage-test-001",
            "name": "Storage Test Schema",
            "fields": {
                "test_field": {
                    "display_name": "Test Field",
                    "type": "string",
                    "required": False
                }
            }
        }

        # Simulate storage failure
        with patch.object(storage, 'save_schema') as mock_save:
            mock_save.side_effect = Exception("Database connection failed")

            try:
                # This will FAIL - components don't exist
                save_response = generator.save_generated_schema({
                    "generated_schema": generated_schema,
                    "save_options": {
                        "enable_backup": True,
                        "retry_on_failure": True
                    }
                })

                # Should attempt backup storage
                assert "backup_location" in save_response
                assert save_response.get("save_status") == "saved_to_backup"

            except Exception as exc_info:
                # If backup also fails, should provide clear error and recovery options
                error_message = str(exc_info)
                assert "storage" in error_message.lower()

                # Should suggest recovery actions
                if hasattr(exc_info, 'recovery_suggestions'):
                    suggestions = exc_info.recovery_suggestions
                    assert isinstance(suggestions, list)
                    assert len(suggestions) > 0

    def test_concurrent_analysis_error_handling(self, sample_pdf_content):
        """Test error handling for concurrent document analysis"""
        # This will FAIL until all components are implemented
        from ai_schema_generation.ui import UploadInterface
        import threading

        uploader = UploadInterface()

        # Multiple documents uploaded simultaneously
        documents = []
        for i in range(5):
            documents.append({
                "content": sample_pdf_content,
                "filename": f"concurrent_test_{i}.pdf"
            })

        upload_results = []
        errors = []

        def upload_document(doc):
            try:
                # This will FAIL - UploadInterface doesn't exist
                result = uploader.upload_sample_document({
                    "document": doc["content"],
                    "filename": doc["filename"]
                })
                upload_results.append(result)
            except Exception as e:
                errors.append(str(e))

        # Start concurrent uploads
        threads = []
        for doc in documents:
            thread = threading.Thread(target=upload_document, args=(doc,))
            threads.append(thread)
            thread.start()

        # Wait for all uploads to complete
        for thread in threads:
            thread.join(timeout=10)

        # Verify error handling for concurrent operations
        if errors:
            for error in errors:
                # Should provide meaningful error messages for concurrency issues
                error_lower = error.lower()
                expected_terms = ["rate limit", "concurrent", "queue", "capacity", "retry"]
                assert any(term in error_lower for term in expected_terms)

        # Some uploads should succeed even under concurrent load
        assert len(upload_results) > 0, "At least some concurrent uploads should succeed"

    def test_memory_exhaustion_handling(self, sample_pdf_content):
        """Test handling of memory exhaustion scenarios"""
        # This will FAIL until all components are implemented
        from ai_schema_generation.services import DocumentProcessor

        processor = DocumentProcessor()

        # Simulate large document processing
        large_document = {
            "id": "memory-test-001",
            "content": sample_pdf_content * 1000,  # Very large content
            "filename": "huge_document.pdf",
            "file_type": "pdf"
        }

        try:
            # This will FAIL - DocumentProcessor doesn't exist
            processing_result = processor.process_document_with_memory_management({
                "document": large_document,
                "memory_limit_mb": 100,
                "enable_streaming": True
            })

            # Should handle large document through streaming
            assert "processing_method" in processing_result
            assert processing_result["processing_method"] == "streaming"

        except MemoryError as exc_info:
            # Should catch memory errors and provide alternatives
            error_message = str(exc_info).lower()
            assert "memory" in error_message

        except Exception as exc_info:
            # Should provide guidance for memory issues
            error_message = str(exc_info).lower()
            if "memory" in error_message or "size" in error_message:
                # Acceptable - should suggest document splitting or other solutions
                pass

    def test_timeout_handling_and_recovery(self, sample_pdf_content):
        """Test handling of analysis timeouts"""
        # This will FAIL until all components are implemented
        from ai_schema_generation.services import AIAnalyzer

        analyzer = AIAnalyzer()

        test_document = {
            "id": "timeout-test-001",
            "content": sample_pdf_content,
            "filename": "complex_document.pdf",
            "file_type": "pdf"
        }

        # Simulate long-running analysis with timeout
        with patch('ai_schema_generation.services.AIAnalyzer._analyze_with_timeout') as mock_analyze:
            mock_analyze.side_effect = TimeoutError("Analysis timeout after 30 seconds")

            # This will FAIL - AIAnalyzer doesn't exist
            try:
                analysis_result = analyzer.analyze_document({
                    "sample_document": test_document,
                    "analysis_options": {
                        "timeout_seconds": 30,
                        "enable_partial_results": True
                    }
                })

                # Should return partial results if available
                if "partial_analysis" in analysis_result:
                    partial = analysis_result["partial_analysis"]
                    assert "fields_extracted" in partial
                    assert "processing_stage" in partial

            except TimeoutError as exc_info:
                # Should provide timeout recovery options
                error_message = str(exc_info)
                assert "timeout" in error_message.lower()

                # Should suggest retry with different parameters
                if hasattr(exc_info, 'retry_suggestions'):
                    suggestions = exc_info.retry_suggestions
                    assert "reduce_complexity" in suggestions or "increase_timeout" in suggestions


if __name__ == "__main__":
    # This test suite will FAIL until comprehensive error handling is implemented
    pytest.main([__file__, "-v"])